2021-11-17 06:47:58,325 ERROR <function format_exc at 0x7fa49d388430>
Traceback (most recent call last):
  File "/news_spider/parser_modules/parsers.py", line 34, in portal_parser
    news_paper = newspaper.build(url, language='ru', memoize_articles=True, config=newspaper_config)
  File "/usr/local/lib/python3.9/site-packages/newspaper/api.py", line 28, in build
    s = Source(url, config=config)
  File "/usr/local/lib/python3.9/site-packages/newspaper/source.py", line 81, in __init__
    self.brand = tldextract.extract(self.url).domain
  File "/usr/local/lib/python3.9/site-packages/tldextract/tldextract.py", line 296, in extract
    return TLD_EXTRACTOR(url, include_psl_private_domains=include_psl_private_domains)
  File "/usr/local/lib/python3.9/site-packages/tldextract/tldextract.py", line 229, in __call__
    suffix_index = self._get_tld_extractor().suffix_index(
  File "/usr/local/lib/python3.9/site-packages/tldextract/tldextract.py", line 270, in _get_tld_extractor
    public_tlds, private_tlds = get_suffix_lists(
  File "/usr/local/lib/python3.9/site-packages/tldextract/suffix_list.py", line 55, in get_suffix_lists
    return cache.run_and_cache(
  File "/usr/local/lib/python3.9/site-packages/tldextract/cache.py", line 186, in run_and_cache
    with FileLock(lock_path, timeout=self.lock_timeout):
  File "/usr/local/lib/python3.9/site-packages/filelock/_api.py", line 199, in __enter__
    self.acquire()
  File "/usr/local/lib/python3.9/site-packages/filelock/_api.py", line 162, in acquire
    raise Timeout(self._lock_file)
filelock._error.Timeout: The file lock '/root/.cache/python-tldextract/3.9.5.final__local__ecb11d__tldextract-3.1.2/publicsuffix.org-tlds/de84b5ca2167d4c83e38fb162f2e8738.tldextract.json.lock' could not be acquired.
